<mujoco>
    <compiler angle="radian" meshdir="assets" autolimits="true"/>
    <option integrator="implicitfast" iterations="100"/>
    <default class="simple">
        <joint damping="1"/>
        <general gaintype="fixed" biastype="affine"/>
    </default>
    <worldbody>
        <body childclass="simple" name="base" pos="0 0 0">
            <body name="link1" pos="0 0 0">
                <joint name="joint1" type="hinge" axis="1 0 0" range="-6.28319 6.28319"/>
                <geom type="capsule" size="0.04 0.2" pos="0 0 0.2" rgba="0 1 0 1" contype="0" conaffinity="0" density="1"/>
                <body name="link3" pos="0 0 0.4">
                    <site name="grip_site" pos="0 0 0"/>
                </body>
            </body>
        </body>
    </worldbody>
    <actuator>
        <position joint="joint1" ctrllimited="true" ctrlrange="-6.28319 6.28319"/>
    </actuator>
</mujoco>
